Workbook

Sheet Cover
B2: Block Inc. | L2: Johann Somosa
C4: Block Inc. is a Fin-Tech company that empowers economic choices through their product and services ecosystem. They improve customers life to acces to their financial services on CashApp, through their P2P money transfer, deposits, withdrawals and lower-rate loans. They enable and improve commerce for businesses on Square through hardware, software, and payment process services. After their recent acquisition, the Company provides purchasing offers through their 'Buy Now, Pay Later' platform. The Company connect artists to their audiences on Tidal through their connections with music labels, high fidelity sound. The Company provides improved pathways for Bitcoin owners on their Bitcoin ecoystem through products Bitkey, Proto, and Spiral.
C6: Price | D6: 65.09 | E6: 46023
C7: Shares outstanding | D7: =559431000+60049000 -> 619480000
C8: Market CAP | D8: =D6*D7 -> 40321953200
C9: Cash | D9: 8075247000
C10: Total Debt | D10: =('BLOCK INC. 3-statement mod'!Q94+'BLOCK INC. 3-statement mod'!Q89)*1000 -> 6105436000
C11: Market Value | D11: =D9+D8-D10 -> 42291764200
B21: Businesses | C21: Type:
B22: Cashapp | C22: Peer-to-peer money transfers, financial services, loans
B23: Square | C23: Commerce and payment process services
B24: Afterpay | C24: Buy Now, Pay Later platform
B25: TIDAL | C25: Music streaming platform
B26: Bitkey | C26: Bitcoin wallet
B27: PROTO | C27: Bitcoin mining
B31: Revenue
B33: Transaction-based Revenue
B34: Collect transaction fees on Square products - net of acquiring interchange and assessment fees, processing fees, and bank settlement fees paid to third-party payment processors
B35: Work with payment card networks and banks, working with complex systems in the payment industry
B36: The Company also charges certain Cash App customers making peer-to-peer transactions using business accounts, or funding transactions with a credit card, a transaction fee that is generally calculated as a percentage of the total transaction amount processed.
B37: Business and credit card transactions between peers have a transaction fee
B40: Subscription and Services-based Revenue
B41: SaaS PRODUCTS
B42: Cash App Instant Deposit, Cash App Card, interest earned on customer funds, bitcoin withdrawal fees, Square Loans, Cash App Borrow, the Company's BNPL platform, TIDAL,
B43: Instant Deposit is a functionality within the Cash App and the Company's managed payments solution that enables customers, including individuals and sellers, to instantly deposit funds into their bank accounts for a percentage-based fee of the amounts deposited. | C43: Within the Cash App, utilizing a Visa Card, the Company charges the customer a per transaction fee when they instantly deposit funds to their bank account or withdraw funds from an ATM. The Company also earns interchange fees when a Cash App Card is used to make a purchase. | D43: Bitcoin withdrawal is a functionality within the Cash App that enables customers to withdraw bitcoin stored on Cash App to a third party wallet. | E43: The Company is restricted from using the stored funds in the Company's operations, the Company may invest a portion of these funds in short-term marketable debt securities to generate interest income which is reported as revenue. | F43: TIDAL primarily generates revenue from subscriptions to its customers, and such subscriptions allow access to the song library, video library, and improved sound quality. charges customers a monthly fee for those subscription services. The Company's contracts with customers are generally for a term of one month and renew automatically each month. The Company invoices its customers monthly
B46: Loans
B47: Square Loans facilitates loans to qualified Square sellers through the Company's subsidiary, Square Financial Services, Inc. ("Square Financial Services"), which is an industrial loan company.
B48: The loans are either repaid through withholding a percentage of the collections of the seller's receivables processed by the Company ("flex loans") or a specified monthly amount ("term loans").
B49: The seller is charged a one-time origination fee based upon their risk rating, which is derived primarily from processing activity.
B50: The Company’s intent to sell all of its rights, title, and interest of these loans to third-party investors for an upfront fee when the loans are sold.
B51: The Company is retained by the third-party investors to service the loans and earns a servicing fee for facilitating the repayment of these receivables through its managed payments solutions.
B53: Cash App Borrow
B54: Credit product for Cash App customers, allows customers to access short-term loans for a small fee.
B55: The loans are originated by the bank partner, from whom the Company purchases the loans obtaining all rights, title, and interest.
B57: BNPL platform
B58: Consumers can pay for their purchases over time by splitting their purchase price into generally three or four installments, typically due in two-week increments, without paying fees (if payments are made on time)
B59: Seller; upfront, less taxes, if applicable, and a merchant fee, which consists of fixed and variable rates as contracted with the sellers | C59: The Company also incurs other costs such as fees paid to third-party partners and processing fees to complete the consumer purchase transaction. | D59: An assumed non-payment risk | E59: The Company sells certain consumer receivables to a third party investor and records the gain or loss on sale as revenue within subscription and services-based revenue | F59: The Company initially recognizes a consumer receivable equal to net amounts paid to the seller plus any costs incurred to originate the consumer receivable. The Company recognizes the merchant fee less costs incurred to originate the consumer receivables as revenue using the effective interest method. | G59: Through the BNPL platform, the Company also has an ads and affiliate program for its merchants. For affiliate relationships, the Company receives a commission when a consumer completes a purchase from within the BNPL platform, which is recognized as a fee earned in connection with the origination of a consumer receivable and recognized as revenue using the effective interest method. | H59: The Company may also receive digital advertising revenue on clicks, typically earned on a cost per click (“CPC”) basis, to merchant sites from the BNPL platform, in addition to flat fees for premium ad placements.
B62: Hardware Revenue
B64: Hardware revenue includes revenue from sales of magstripe readers, contactless and chip readers, Square Stand, Square Register, Square Terminal, and third-party peripherals.
B65: Third-party peripherals include cash drawers, receipt printers, scales, and barcode scanners, all of which can be integrated with Square Stand, Square Register, or Square Terminal to provide a comprehensive point-of-sale solution.
...

Sheet BLOCK INC. 3-statement mod
B1: Block Inc. | R1: Johann Somosa
B3: Market CAP | O3: =(Cover!D7*Cover!D6)*0.001 -> 40321953
B5: Assumptions & Drivers | C5: Historicals | O5: Historicals | S5: Forecast
B6: All figures in USD thousands unless indicated | C6: Q122 | D6: Q222 | E6: Q322 | F6: Q123 | G6: Q223 | H6: Q323 | I6: Q124 | J6: Q224 | K6: Q324 | L6: Q125 | M6: Q225 | O6: 44926 | P6: =EOMONTH(O6,12) -> 45291 | Q6: =EOMONTH(P6,12) -> 45657 | R6: =EOMONTH(Q6,12) -> 46022 | S6: =EOMONTH(R6,12) -> 46387 | T6: =EOMONTH(S6,12) -> 46752 | U6: =EOMONTH(T6,12) -> 47118 | V6: =EOMONTH(U6,12) -> 47483 | W6: =EOMONTH(V6,12) -> 47848
C7: 44651 | D7: =EOMONTH(C7,3) -> 44742 | E7: =EOMONTH(D7,3) -> 44834 | F7: 45016 | G7: =EOMONTH(F7,3) -> 45107 | H7: =EOMONTH(G7,3) -> 45199 | I7: 45382 | J7: =EOMONTH(I7,3) -> 45473 | K7: =EOMONTH(J7,3) -> 45565 | L7: 45747 | M7: =EOMONTH(L7,3) -> 45838
B8: Days in Period | O8: 365 | P8: 365 | Q8: 365 | R8: 365 | S8: 365 | T8: 365 | U8: 365 | V8: 365 | W8: 365
B10: Best Case
B11: Revenue Growth | D11: =D41/C41-1 -> 0.11206609 | E11: =E41/D41-1 -> 0.02521104 | F11: =F41/E41-1 -> 0.10510147 | G11: =G41/F41-1 -> 0.1091807 | H11: =H41/G41-1 -> 0.014911769 | I11: =I41/H41-1 -> 0.060460244 | J11: =J41/I41-1 -> 0.033310515 | K11: =K41/J41-1 -> -0.029203178 | ... M11: =M41/L41-1 -> 0.048972798 | P11: =$P$41/$O$41-1 -> 0.25006498 | Q11: =$Q$41/$P$41-1 -> 0.10063278 | R11: =(1+$L$11)*(1+$M$11)*(1+0.08)*(1+0.08)-1 -> 0.18175265 | S11: =AVERAGE(P11:R11) -> 0.17748347 | T11: =AVERAGE(Q11:S11) -> 0.15328963 | U11: =AVERAGE(R11:T11) -> 0.17084192 | V11: =AVERAGE(S11:U11) -> 0.167205 | W11: =AVERAGE(T11:V11) -> 0.16377885
B12: COGS Margin (Percentage of Revenue) | D12: =D46/D41 -> 0.66633027 | E12: =E46/E41 -> 0.65295653 | F12: =F46/F41 -> 0.65640501 | G12: =G46/G41 -> 0.66285176 | H12: =H46/H41 -> 0.66204693 | I12: =I46/I41 -> 0.64840893 | J12: =J46/J41 -> 0.63716073 | K12: =K46/K41 -> 0.62353415 | ... M12: =M46/M41 -> 0.58104748 | O12: =O46/O41 -> 0.65822307 | P12: =P46/P41 -> 0.65755543 | Q12: =Q46/Q41 -> 0.63148226 | R12: =R46/R41 -> 0.6 | S12: =S46/S41 -> 0.6 | T12: =T46/T41 -> 0.6 | U12: =U46/U41 -> 0.6 | V12: =V46/V41 -> 0.6 | W12: =W36/W31 -> #DIV/0!
B13: Gross Margin | D13: =D47/D41 -> 0.33366973 | E13: =E47/E41 -> 0.34704347 | F13: =F47/F41 -> 0.34359499 | G13: =G47/G41 -> 0.33714824 | H13: =H47/H41 -> 0.33795307 | I13: =I47/I41 -> 0.35159107 | J13: =J47/J41 -> 0.36283927 | K13: =K47/K41 -> 0.37646585 | ... M13: =M47/M41 -> 0.41895252 | O13: =O47/O41 -> 0.34177693 | P13: =P47/P41 -> 0.34244457 | Q13: =Q47/Q41 -> 0.36851774 | R13: =R47/R41 -> 0.4 | S13: =S47/S41 -> 0.4 | T13: =T47/T41 -> 0.4 | U13: =U47/U41 -> 0.4 | V13: =V47/V41 -> 0.4 | W13: =W37/W31 -> #DIV/0!
B14: Operating Income Margin | D14: =D52/D41 -> -0.031427638 | E14: =E52/E41 -> 0.030511737 | F14: =F52/F41 -> 0.0061952281 | G14: =G52/G41 -> -0.01720736 | H14: =H52/H41 -> 0.0083768685 | I14: =I52/I41 -> 0.049188972 | J14: =J52/J41 -> 0.056432693 | K14: =K52/K41 -> 0.060080649 | ... M14: =M52/M41 -> 0.085587196 | O14: =O52/O41 -> -0.025052096 | P14: =P52/P41 -> -0.0047817486 | Q14: =Q52/Q41 -> 0.043407558 | R14: =R52/R41 -> 0.09 | S14: 0.05 | T14: 0.05 | U14: 0.01 | V14: 0.01 | W14: 0.02
B15: Profit Margin | D15: =D57/D41 -> -0.030406864 | E15: =E57/E41 -> 0.037165425 | F15: =F57/F41 -> 0.0027351987 | G15: =G57/G41 -> -0.016075464 | H15: =H57/H41 -> 0.0041308463 | I15: =I57/I41 -> 0.047119686 | J15: =J57/J41 -> 0.048866529 | K15: =K57/K41 -> 0.053073554 | ... M15: =M57/M41 -> 0.059470238 | O15: =O57/O41 -> -0.020972203 | P15: =P57/P41 -> -0.0024714789 | Q15: =Q57/Q41 -> 0.1078016 | R15: =R57/R41 -> 0.077860326 | S15: =S57/S41 -> 0.088015638 | T15: =T57/T41 -> 0.089177941 | U15: =U57/U41 -> 0.090201411 | V15: =V57/V41 -> 0.091341247 | W15: =W47/W31 -> #DIV/0!
B16: Maketing Costs (Percentage of Sales) | D16: =D48/D41 -> 0.21036377 | E16: =E48/E41 -> 0 | F16: =F48/F41 -> 0.18613459 | G16: =G48/G41 -> 0.19637009 | H16: =H48/H41 -> 0.17094209 | I16: =I48/I41 -> 0.15362185 | J16: =J48/J41 -> 0.15938916 | K16: =K48/K41 -> 0.16526822 | ... M16: =M48/M41 -> 0.16499713 | O16: =O48/O41 -> 0.21360302 | P16: =P48/P41 -> 0.19293081 | Q16: =Q48/Q41 -> 0.17135919 | R16: 0.16 | S16: 0.15 | T16: 0.15 | U16: 0.15 | V16: 0.15 | W16: 0.15
B17: Product Development Costs (Percentage of Sales) | D17: =D49/D41 -> 0.11915703 | E17: =E49/E41 -> 0.12136685 | F17: =F49/F41 -> 0.12563538 | G17: =G49/G41 -> 0.1255063 | H17: =H49/H41 -> 0.12706522 | I17: =I49/I41 -> 0.12095997 | J17: =J49/J41 -> 0.11585666 | K17: =K49/K41 -> 0.11897702 | ... M17: =M49/M41 -> 0.11979406 | O17: =O49/O41 -> 0.1218151 | P17: =P49/P41 -> 0.12414974 | Q17: =Q49/Q41 -> 0.12082453 | R17: 0.12 | S17: 0.12 | T17: 0.12 | U17: 0.12 | V17: 0.12 | W17: 0.12
B18: Transaction, Loans, and Consumer Receivable Losses (Percentage of Sales) | D18: =D50/D41 -> 0.035576577 | E18: =E50/E41 -> 0.19516488 | F18: =F50/F41 -> 0.025629788 | G18: =G50/G41 -> 0.032479204 | H18: =H50/H41 -> 0.031568887 | I18: =I50/I41 -> 0.027820285 | J18: =J50/J41 -> 0.031160757 | K18: =K50/K41 -> 0.032139959 | ... M18: =M50/M41 -> 0.048574133 | O18: =O50/O41 -> 0.031410904 | P18: =P50/P41 -> 0.030145755 | Q18: =Q50/Q41 -> 0.032926465 | R18: 0.03 | S18: 0.03 | T18: 0.03 | U18: 0.03 | V18: 0.03 | W18: 0.03
B19: Tax Rate | D19: =-D56/D55 -> -0.009832382 | E19: =-E56/E55 -> -0.11485189 | F19: =-F56/F55 -> 0.13091372 | G19: =-G56/G55 -> 0.039923606 | H19: =-H56/H55 -> 0.68096076 | I19: =-I56/I55 -> 0.11224896 | J19: =-J56/J55 -> 0.16404691 | K19: =-K56/K55 -> 0.11941927 | ... M19: =-M56/M55 -> 0.25160255 | O19: =-O56/O55 -> 0.032401023 | P19: =-P56/P55 -> 0.12895808 | Q19: =-Q56/Q55 -> -1.3835189 | R19: =AVERAGE($I$19:$M$19) -> 0.15111429 | S19: =AVERAGE($I$19:$M$19) -> 0.15111429 | T19: =AVERAGE($I$19:$M$19) -> 0.15111429 | U19: =AVERAGE($I$19:$M$19) -> 0.15111429 | V19: =AVERAGE($I$19:$M$19) -> 0.15111429 | W19: =AVERAGE($I$19:$M$19) -> 0.15111429
B25: Liquidity Ratio | P25: =P74/P90 -> 2.0059224 | Q25: =Q74/Q90 -> 2.3260408
B26: Quick Ratio | P26: =(P69+P70+P71)/P90 -> 1.2967801 | Q26: =(Q69+Q70+Q71)/Q90 -> 1.4092433
B27: Financial Leverage Ratio | P27: =AVERAGE(O83:P83)/AVERAGE(O105:P105) -> 1.7670571 | Q27: =AVERAGE(P83:Q83)/AVERAGE(P105:Q105) -> 1.7483785
B28: Loan Turnover Ratio (Sales Basis) | P28: =P41/P72 -> 28.262761 | Q28: =Q41/Q72 -> 21.709028
B29: Capital Asset Turnover Ratio | P29: =P41/AVERAGE(O83:P83) -> 0.66348033 | Q29: =Q41/AVERAGE(P83:Q83) -> 0.69105951
B30: Payable Days (COGS Basis) | P30: =(AVERAGE(O88:P88))/P46*365 -> 33.804946 | Q30: =(AVERAGE(P88:Q88))/Q46*365 -> 34.264457
B31: Return on Assets | P31: =P57/AVERAGE(O83:P83) -> -0.0016397776 | Q31: =Q57/AVERAGE(P83:Q83) -> 0.074497317
B32: Return On Capital Earnings | P32: =P52/(P83-P90) -> -0.0043396494 | Q32: =Q52/(Q83-Q90) -> 0.037088432
B34: DTA | P34: 0.43408732 | Q34: 0.42261146
B35: DTE | P35: 0.76705707 | Q35: 0.73193599
B38: Income Statement
C39: Q122 | D39: Q222 | E39: Q322 | F39: Q123 | G39: Q223 | H39: Q323 | I39: Q124 | J39: Q224 | K39: Q324 | L39: Q125 | M39: Q225 | O39: 44926 | P39: =EOMONTH(O39,12) -> 45291 | Q39: =EOMONTH(P39,12) -> 45657 | R39: =EOMONTH(Q39,12) -> 46022 | S39: =EOMONTH(R39,12) -> 46387 | T39: =EOMONTH(S39,12) -> 46752 | U39: =EOMONTH(T39,12) -> 47118 | V39: =EOMONTH(U39,12) -> 47483 | W39: =EOMONTH(V39,12) -> 47848
C40: 44651 | D40: =EOMONTH(C40,3) -> 44742 | E40: =EOMONTH(D40,3) -> 44834 | F40: 45016 | G40: =EOMONTH(F40,3) -> 45107 | H40: =EOMONTH(G40,3) -> 45199 | I40: 45382 | J40: =EOMONTH(I40,3) -> 45473 | K40: =EOMONTH(J40,3) -> 45565 | L40: 45747 | M40: =EOMONTH(L40,3) -> 45838
B41: Revenue | C41: =SUM(C42:C45) -> 3960645 | D41: =SUM(D42:D45) -> 4404499 | E41: =SUM(E42:E45) -> 4515541 | F41: =SUM(F42:F45) -> 4990131 | G41: =SUM(G42:G45) -> 5534957 | H41: =SUM(H42:H45) -> 5617493 | I41: 5957128 | J41: 6155563 | K41: 5975801 | L41: 5771796 | M41: 6054457 | O41: 17531587 | P41: 21915623 | Q41: 24121053 | R41: =Q41*(1+R11) -> 28505118 | S41: =R41*(1+S11) -> 33564305 | T41: =S41*(1+T11) -> 38709365 | U41: =T41*(1+U11) -> 45322548 | V41: =U41*(1+V11) -> 52900704 | W41: =V41*(1+W11) -> 61564721
B42: Transaction-based revenue | C42: 1232969 | D42: 1475707 | E42: 1517890 | F42: 1422705 | G42: 1637654 | H42: 1658668 | O42: 5701540 | P42: 6315301 | Q42: 6613680
B43: Subscription and services-based revenue | C43: 959557 | D43: 1094856 | E43: 1191511 | F43: 1366224 | G43: 1461497 | H43: 1492900 | O43: 4552773 | P43: 5944842 | Q43: 7164799
B44: Hardware revenue | C44: 37326 | D44: 48051 | E44: 43388 | F44: 37451 | G44: 44922 | H44: 42341 | O44: 164418 | P44: 157178 | Q44: 143369
B45: Bitcoin revenue | C45: 1730793 | D45: 1785885 | E45: 1762752 | F45: 2163751 | G45: 2390884 | H45: 2423584 | O45: 7112856 | P45: 9498302 | Q45: 10199205
B46: COGS | C46: 2665685 | D46: 2934851 | E46: 2948452 | F46: 3275547 | G46: 3668856 | H46: 3719044 | I46: 3862655 | J46: 3922083 | K46: 3726116 | L46: 3482193 | M46: 3517927 | O46: 11539695 | P46: 14410737 | Q46: 15232017 | R46: =R41*0.6 -> 17103071 | S46: =S41*0.6 -> 20138583 | T46: =T41*0.6 -> 23225619 | U46: =U41*0.6 -> 27193529 | V46: =V41*0.6 -> 31740423 | W46: =W41*0.6 -> 36938833
B47: Gross Profit | C47: =C41-C46 -> 1294960 | D47: =D41-D46 -> 1469648 | E47: =E41-E46 -> 1567089 | F47: =F41-F46 -> 1714584 | G47: =G41-G46 -> 1866101 | H47: =H41-H46 -> 1898449 | I47: =I41-I46 -> 2094473 | J47: =J41-J46 -> 2233480 | ... M47: =M41-M46 -> 2536530 | N47: 2600000 | O47: =O41-O46 -> 5991892 | P47: =P41-P46 -> 7504886 | Q47: =Q41-Q46 -> 8889036 | R47: =R41-R46 -> 11402047 | S47: =S41-S46 -> 13425722 | T47: =T41-T46 -> 15483746 | U47: =U41-U46 -> 18129019 | V47: =V41-V46 -> 21160282 | W47: =W41-W46 -> 24625888
B48: Selling, general, & administrative expenses | C48: =501562+444149 -> 945711 | D48: =530827+395720 -> 926547 | F48: =496011+432825 -> 928836 | G48: =537607+549293 -> 1086900 | H48: =479381+480885 -> 960266 | I48: =443885+471260 -> 915145 | J48: =507562+473568 -> 981130 | K48: =511755+475855 -> 987610 | L48: =504460+491797 -> 996257 | M48: =549731+449237 -> 998968 | O48: =2057951+1686849 -> 3744800 | P48: =2019009+2209190 -> 4228199 | Q48: =1984265+2149099 -> 4133364 | R48: =R41*R16 -> 4560818.9 | S48: =S41*S16 -> 5034645.8 | T48: =T41*T16 -> 5806404.8 | U48: =U41*U16 -> 6798382.1 | V48: =V41*V16 -> 7935105.7 | W48: =W41*W16 -> 9234708.1
B49: Product development | C49: 458224 | D49: 524827 | E49: 548037 | F49: 626937 | G49: 694672 | H49: 713788 | I49: =720574 -> 720574 | J49: 713163 | K49: =710983 -> 710983 | L49: 760699 | M49: 725288 | O49: 2135612 | P49: =2720819 -> 2720819 | Q49: 2914415 | R49: =R41*R17 -> 3420614.2 | S49: =S41*S17 -> 4027716.7 | T49: =T41*T17 -> 4645123.9 | U49: =U41*U17 -> 5438705.7 | V49: =V41*V17 -> 6348084.5 | W49: =W41*W17 -> 7387766.5
B50: Transactions, loans, and consumer receivable losses | C50: 91150 | D50: 156697 | E50: =485838+395437 -> 881275 | F50: 127896 | G50: 179771 | H50: 177338 | I50: 165729 | J50: 191812 | K50: =192062 -> 192062 | L50: 169689 | M50: 294090 | O50: 550683 | P50: 660663 | Q50: 794221 | R50: =R41*R18 -> 855153.55 | S50: =R50*(1+0.1) -> 940668.9 | T50: =S50*(1+0.1) -> 1034735.8 | U50: =T50*(1+0.1) -> 1138209.4 | V50: =U50*(1+0.1) -> 1252030.3 | W50: =V50*(1+0.1) -> 1377233.3
B51: Operating Expenses | C51: =SUM(C48:C50) -> 1495085 | D51: =SUM(D48:D50) -> 1608071 | E51: =SUM(E48:E50) -> 1429312 | F51: =SUM(F48:F50) -> 1683669 | G51: =SUM(G48:G50) -> 1961343 | H51: =SUM(H48:H50) -> 1851392 | I51: =SUM(I48:I50) -> 1801448 | J51: =SUM(J48:J50) -> 1886105 | ... M51: =SUM(M48:M50) -> 2018346 | O51: =SUM(O48:O50) -> 6431095 | P51: =SUM(P48:P50) -> 7609681 | Q51: =SUM(Q48:Q50) -> 7842000 | R51: =SUM(R48:R50) -> 8836586.6 | S51: =SUM(S48:S50) -> 10003031 | T51: =SUM(T48:T50) -> 11486264 | U51: =SUM(U48:U50) -> 13375297 | V51: =SUM(V48:V50) -> 15535220 | W51: =SUM(W48:W50) -> 17999708
...

Sheet DCF Analysis
B3: Free Cash Flow
B4: Period | C4: 44926 | D4: =EOMONTH(C4,12) -> 45291 | E4: =EOMONTH(D4,12) -> 45657
B5: Free Cash Flow | C5: ='BLOCK INC. 3-statement mod'!O57 -> -367676 | D5: ='BLOCK INC. 3-statement mod'!P57 -> -54164 | E5: ='BLOCK INC. 3-statement mod'!Q57 -> 2600288
B7: Ratios:
B8: Average Growth Rate | D8: =(D5-C5)/C5 -> -0.85268552 | E8: =(E5-D5)/-D5 -> 49.00768
B10: Forecasted Free Cash Flow | C10: 1 | D10: =C10+1 -> 2 | E10: =D10+1 -> 3 | F10: =E10+1 -> 4 | G10: =F10+1 -> 5 | H10: =G10+1 -> 6 | I10: =H10+1 -> 7 | J10: =I10+1 -> 8 | K10: =J10+1 -> 9 | ... M10: =L10+1 -> 11 | O10: =M10+1 -> 12 | P10: =O10+1 -> 13 | Q10: =P10+1 -> 14 | R10: =Q10+1 -> 15 | S10: =R10+1 -> 16 | T10: =S10+1 -> 17 | U10: =T10+1 -> 18 | V10: =U10+1 -> 19 | W10: =V10+1 -> 20 | ... AH10: =AG10+1 -> 31
B11: Period | C11: 46022 | D11: =EOMONTH(C11,12) -> 46387 | E11: =EOMONTH(D11,12) -> 46752 | F11: =EOMONTH(E11,12) -> 47118 | G11: =EOMONTH(F11,12) -> 47483 | H11: =EOMONTH(G11,12) -> 47848 | I11: =EOMONTH(H11,12) -> 48213 | J11: =EOMONTH(I11,12) -> 48579 | K11: =EOMONTH(J11,12) -> 48944 | ... M11: =EOMONTH(L11,12) -> 49674 | O11: =EOMONTH(M11,12) -> 50040 | P11: =EOMONTH(O11,12) -> 50405 | Q11: =EOMONTH(P11,12) -> 50770 | R11: =EOMONTH(Q11,12) -> 51135 | S11: =EOMONTH(R11,12) -> 51501 | T11: =EOMONTH(S11,12) -> 51866 | U11: =EOMONTH(T11,12) -> 52231 | V11: =EOMONTH(U11,12) -> 52596 | W11: =EOMONTH(V11,12) -> 52962 | ... AH11: =EOMONTH(AG11,12) -> 56979
B12: Forecasted Free Cash Flow | C12: {='BLOCK INC. 3-statement mod'!#REF!} -> #REF! | T12: =S12*(1+$C$15) -> 0 | U12: =T12*(1+$C$15) -> 0 | V12: =U12*(1+$C$15) -> 0 | W12: =V12*(1+$C$15) -> 0 | X12: =W12*(1+$C$15) -> 0 | Y12: =X12*(1+$C$15) -> 0 | Z12: =Y12*(1+$C$15) -> 0 | AA12: =Z12*(1+$C$15) -> 0 | ... AH12: =AG12*(1+$C$15) -> 0
B13: PV of FFCF | C13: =C12*(1-$C$24)^C10 -> #REF! | D13: =D12*(1-$C$24)^D10 -> 0 | E13: =E12*(1-$C$24)^E10 -> 0 | F13: =F12*(1-$C$24)^F10 -> 0 | G13: =G12*(1-$C$24)^G10 -> 0 | H13: =H12*(1-$C$24)^H10 -> 0 | I13: =I12*(1-$C$24)^I10 -> 0 | J13: =J12*(1-$C$24)^J10 -> 0 | ... M13: =M12*(1-$C$24)^M10 -> 0 | O13: =O12*(1-$C$24)^O10 -> 0 | P13: =P12*(1-$C$24)^P10 -> 0 | Q13: =Q12*(1-$C$24)^Q10 -> 0 | R13: =R12*(1-$C$24)^R10 -> 0 | S13: =S12*(1-$C$24)^S10 -> 0 | T13: =T12*(1-$C$24)^T10 -> 0 | U13: =U12*(1-$C$24)^U10 -> 0 | V13: =V12*(1-$C$24)^V10 -> 0 | ... AH13: =AH12*(1-$C$24)^AH10 -> 0
B15: Perpetual Growth Rate | C15: 0.02
B18: WACC
B19: Debt | C19: =('BLOCK INC. 3-statement mod'!Q89+'BLOCK INC. 3-statement mod'!Q94)/('BLOCK INC. 3-statement mod'!Q89+'BLOCK INC. 3-statement mod'!Q94+'BLOCK INC. 3-statement mod'!Q105) -> 0.22331189
B20: Equity | C20: ='BLOCK INC. 3-statement mod'!Q105/('BLOCK INC. 3-statement mod'!Q89+'BLOCK INC. 3-statement mod'!Q94+'BLOCK INC. 3-statement mod'!Q105) -> 0.77668811
B21: Cost of Equity | C21: =0.0408+2.71*(0.08-0.0408) -> 0.147032
B22: Cost of Debt | C22: 0.06
B23: Corporate Tax Rate | C23: 0.12
B24: WACC | C24: =(C19*C23*C22)+(C20*C21) -> 0.11580585
B27: Discounting
B28: Discount Factor | C28: =C24 -> 0.11580585
B29: PV of FFCF | C29: =SUM(C13:AH13) -> #REF!
B30: PV of TV | C30: =AH12*(1+$C$15)/(C$24-$C$15) -> 0
B31: Enterprise Value | C31: =C29+C30 -> #REF!
B33: Total Debt | C33: ='BLOCK INC. 3-statement mod'!Q89+'BLOCK INC. 3-statement mod'!Q94 -> 6105436
B34: Cash | C34: ='BLOCK INC. 3-statement mod'!Q69 -> 8075247
B35: Marketable Securities | C35: ='BLOCK INC. 3-statement mod'!Q70 -> 403426
B36: Equity Value | C36: =C31-C33+C34+C35 -> #REF!
B38: Shares Outstanding | C38: 619480
B39: Implied Shared Price | C39: =C36/C38 -> #REF!
B41: EV/E | C41: =C31/'BLOCK INC. 3-statement mod'!Q57 -> #REF!
B43: Sensitivity Analysis
B45: Assumptions 1
B46: Growth Rate | C46: 0.35
B47: Perpetuity Growth Rate | C47: =(1+0.04)^0.25-1 -> 0.0098534065
B50: Debt | C50: 0.22331189
B51: Equity | C51: 0.78
B52: Cost of Equity | C52: =0.04+1*(0.25-0.04) -> 0.25
B53: Cost of Debt | C53: 0.06
B54: Corporate Tax Rate | C54: 0.15
B55: WACC | C55: =(C50*C54*C53)+(C51*C52) -> 0.19700981
B57: Quarterly WACC | C57: =(1+C55)^0.25-1 -> 0.045982521
...

Sheet Segment Revenue
B2: Segment (Year ended in Dec. 31, 2024)
C4: Cash App | D4: Square | E4: Corporate and Other | F4: Total
B5: Transaction-based revenue | C5: 352699 | D5: 6260981 | E5: — | F5: =SUM(C5:E5) -> 6613680
B6: Subscription and services-based revenue | C6: 5695976 | D6: 1278933 | E6: 189890 | F6: =SUM(C6:E6) -> 7164799
B7: Hardware revenue | C7: — | D7: 141742 | E7: 1627 | F7: =SUM(C7:E7) -> 143369
B8: Bitcoin revenue | C8: 10199205 | D8: — | E8: — | F8: =SUM(C8:E8) -> 10199205
B9: Segment revenue | C9: =SUM(C5:C8) -> 16247880 | D9: =SUM(D5:D8) -> 7681656 | E9: =SUM(E5:E8) -> 191517 | F9: =SUM(C9:E9) -> 24121053
B10: Less: Cost of revenue | C10: 11008869 | D10: 4082744 | E10: 140404 | F10: =SUM(C10:E10) -> 15232017
B11: Segment gross profit | C11: =C9-C10 -> 5239011 | D11: =D9-D10 -> 3598912 | E11: =E9-E10 -> 51113 | F11: =SUM(C11:E11) -> 8889036
F12: =SUM(C12:E12) -> 0
B13: Interest revenue | C13: 185185 | D13: 36837 | E13: — | F13: =SUM(C13:E13) -> 222022
B14: Amortization of acquired technology assets | C14: 55343 | D14: 7726 | E14: 5295 | F14: =SUM(C14:E14) -> 68364
B16: Financial Ratios:
B17: Gross Profit Margin | C17: =C11/C9 -> 0.32244274 | D17: =D11/D9 -> 0.46850731 | E17: =E11/E9 -> 0.26688492 | F17: =F11/F9 -> 0.36851774
B21: Segment (Year ended in Dec. 31, 2023)
C23: Cash App | D23: Square | E23: Corporate and Other | F23: Total
B24: Transaction-based revenue | C24: 498176 | D24: 5817125 | E24: — | F24: =SUM(C24:E24) -> 6315301
B25: Subscription and services-based revenue | C25: 4685208 | D25: 1059081 | E25: 205646 | F25: =SUM(C25:E25) -> 5949935
B26: Hardware revenue | D26: 157178 | E26: — | F26: =SUM(C26:E26) -> 157178
B27: Bitcoin revenue | C27: 9498302 | E27: — | F27: =SUM(C27:E27) -> 9498302
B28: Segment revenue | C28: =SUM(C24:C27) -> 14681686 | D28: =SUM(D24:D27) -> 7033384 | E28: =SUM(E24:E27) -> 205646 | F28: =SUM(C28:E28) -> 21920716
B29: Less: Cost of revenue | C29: 10358223 | D29: 3904730 | E29: 147784 | F29: =SUM(C29:E29) -> 14410737
B30: Segment gross profit | C30: =C28-C29 -> 4323463 | D30: =D28-D29 -> 3128654 | E30: =E28-E29 -> 57862 | F30: =SUM(C30:E30) -> 7509979
B31: Interest revenue | C31: 142222 | D31: 28011 | E31: - | F31: =SUM(C31:E31) -> 170233
B32: Amortization of acquired technology assets | C32: 56135 | D32: 10632 | E32: 6062 | F32: =SUM(C32:E32) -> 72829
B34: Financial Ratios:
B35: Gross Profit Margin | C35: =C30/C28 -> 0.29448001 | D35: =D30/D28 -> 0.44482912 | E35: =E30/E28 -> 0.28136701 | F35: =F30/F28 -> 0.34259734
B38: Segment (Year ended in Dec. 31, 2022)
C40: Cash App | D40: Square | E40: Corporate and Other | F40: Total
B41: Transaction-based revenue | C41: 466171 | D41: 5235369 | E41: — | F41: =SUM(C41:E41) -> 5701540
B42: Subscription and services-based revenue | C42: 3452777 | D42: 894350 | E42: 205646 | F42: =SUM(C42:E42) -> 4552773
B43: Hardware revenue | C43: — | D43: 164418 | E43: — | F43: =SUM(C43:E43) -> 164418
B44: Bitcoin revenue | C44: 7112856 | D44: — | E44: — | F44: =SUM(C44:E44) -> 7112856
B45: Segment revenue | C45: =SUM(C41:C44) -> 11031804 | D45: =SUM(D41:D44) -> 6294137 | E45: =SUM(E41:E44) -> 205646 | F45: =SUM(C45:E45) -> 17531587
B46: Less: Cost of revenue | C46: 7786760 | D46: 3587236 | E46: 165699 | F46: =SUM(C46:E46) -> 11539695
B47: Segment gross profit | C47: =C45-C46 -> 3245044 | D47: =D45-D46 -> 2706901 | E47: =E45-E46 -> 39947 | F47: =SUM(C47:E47) -> 5991892
B49: Interest revenue | C49: 29026 | D49: 1193 | E49: — | F49: =SUM(C49:E49) -> 30219
B50: Amortization of acquired technology assets | C50: 53900 | D50: 10494 | E50: 5800 | F50: =SUM(C50:E50) -> 70194
B53: Financial Ratios:
B54: Gross Profit Margin | C54: =C47/C45 -> 0.29415352 | D54: =D47/D45 -> 0.43006706 | E54: =E47/E45 -> 0.19425129 | F54: =F47/F45 -> 0.34177693
...

Sheet Business Information
B3: Price
B4: Shares
B5: Mk
B32: Businesses | C32: Type:
B33: Investments into AI open source building
B34: Small consumer and business loans through CashApp
B35: companies - FINTECH:
B36: Cashapp | C36: Peer-to-peer money transfers, loans
B37: Square | C37: Commerce and payment process services
B38: Afterpay | C38: Buy Now, Pay Later platform
B39: TIDAL | C39: Music
B40: bitkey | C40: Bitcoin wallet
B41: PROTO | C41: Bitcoin mining
B45: Revenue -Recongition
B46: Transaction-based Revenue
B47: Collect transaction fees on Square products - net of acquiring interchange and assessment fees, processing fees, and bank settlement fees paid to third-party payment processors
B48: Work with payment card networks and banks, working with complex systems in the payment industry
B49: The Company also charges certain Cash App customers making peer-to-peer transactions using business accounts, or funding transactions with a credit card, a transaction fee that is generally calculated as a percentage of the total transaction amount processed.
B50: Revenue is recognized on authorization of the seller's customer's bank.
B51: Business and credit card transactions between peers have a transaction fee
B53: Subscription and Services-based Revenue
B54: SaaS PRODUCTS
B55: Cash App Instant Deposit, Cash App Card, interest earned on customer funds, bitcoin withdrawal fees, Square Loans, Cash App Borrow, the Company's BNPL platform, TIDAL,
B56: Instant Deposit is a functionality within the Cash App and the Company's managed payments solution that enables customers, including individuals and sellers, to instantly deposit funds into their bank accounts for a percentage-based fee of the amounts deposited.
B57: Within the Cash App, utilizing a Visa Card, the Company charges the customer a per transaction fee when they instantly deposit funds to their bank account or withdraw funds from an ATM. The Company also earns interchange fees when a Cash App Card is used to make a purchase.
... B134: Transaction-based revenue, hardware, and subscription-based, BNPL`
B135: Q1 | C135: Weak
B136: Q2
B137: Q3
B138: Q4 | C138: Strong
B140: Reasons:
B141: Their sellers typically generate large GPV during holiday season.
B143: CashApp
B144: Historically, our Cash App ecosystem has experienced improvements in revenue, gross profit, and inflows related to the distribution of government funds as customers have deposited more funds into Cash App during these times, including during the first quarter when U.S. tax refunds are typically distributed.
B146: Market
B147: CashApp: Cash App is aiming to become one of the top providers of banking services to households in the United States that earn up to $150,000 per year
B149: 2025 Q2 Earnings Report
B150: Gross profit was $2.5 billion, up 14% year over year, accelerating from 9% growth last quarter.
B151: Pay Monthly for Afterpay Single Use Payments in the U.S.
B152: Sauce: we provide what we believe is the only way to buy bitcoin with no fees and no spread
...

Sheet Sheet1
A2: Cash flows from operating activities: | B2: 2024 | C2: 2023 | D2: 2022
A3: Net income (loss) | B3: 2,866,497 | C3: (21,124) | D3: (553,005)
A4: Adjustments to reconcile net income (loss) to net cash provided by operating activities:
A5: Depreciation and amortization | B5: 376,127 | C5: 408,560 | D5: 340,523
A6: Amortization of discounts and premiums and other non-cash adjustments | B6: (1,099,024) | C6: (984,442) | D6: (592,489)
A7: Non-cash lease expense | B7: 72,055 | C7: 144,198 | D7: 129,811
A8: Share-based compensation | B8: 1,272,779 | C8: 1,276,097 | D8: 1,071,278
A9: Loss (gain) on revaluation of equity investments | B9: (32,245) | C9: 16,523 | D9: (73,457)
A10: Remeasurement gain on bitcoin investment | B10: (420,918) | C10: (207,084) | D10: —
A11: Transaction, loan, and consumer receivable losses | B11: 794,221 | C11: 660,663 | D11: 550,683
A12: Bitcoin impairment losses | B12: — | C12: — | D12: 46,571
A13: Change in deferred income taxes | B13: (1,665,812) | C13: (85,879) | D13: (69,593)
A14: Goodwill and intangible asset impairment | B14: 133,853 | C14: 132,313 | D14: —
A15: Changes in operating assets and liabilities:
A16: Settlements receivable | B16: 1,947,849 | C16: (1,108,529) | D16: (1,499,057)
A17: Purchases and originations of loans | B17: (15,210,746) | C17: (8,586,293) | D17: (6,114,847)
A18: Proceeds from payments and forgiveness of loans | B18: 14,413,277 | C18: 8,032,687 | D18: 6,040,369
A19: Customers payable | B19: (1,853,872) | C19: 1,256,578 | D19: 1,060,861
A20: Settlements payable | B20: (8,139) | C20: (454,036) | D20: 207,894
A21: Other assets and liabilities | B21: 121,448 | C21: (379,271) | D21: (369,639)
A22: Net cash provided by operating activities | B22: 1,707,350 | C22: 100,961 | D22: 175,903
A23: Cash flows from investing activities:
A24: Purchases of marketable debt securities | B24: (1,197,804) | C24: (1,126,615) | D24: (755,697)
A25: Proceeds from maturities of marketable debt securities | B25: 1,005,580 | C25: 1,387,830 | D25: 999,569
A26: Proceeds from sale of marketable debt securities | B26: 446,076 | C26: 339,095 | D26: 449,723
A27: Proceeds from maturities of marketable debt securities from customer funds | B27: — | C27: — | D27: 73,000
A28: Proceeds from sale of marketable debt securities from customer funds | B28: — | C28: — | D28: 316,576
A29: Payments for originations of consumer receivables | B29: (29,318,390) | C29: (23,968,787) | D29: (18,361,871)
A30: Proceeds from principal repayments and sales of consumer receivables | B30: 29,922,371 | C30: 24,241,651 | D30: 18,192,470
A31: Purchases of property and equipment | B31: (153,947) | C31: (151,151) | D31: (170,815)
A32: Purchases of other investments | B32: (53,934) | C32: (38,822) | D32: (56,712)
A33: Business combinations, net of cash acquired | B33: — | C33: — | D33: 539,453
A34: Net cash provided by investing activities | B34: 649,952 | C34: 683,201 | D34: 1,225,696
A36: Cash flows from financing activities:
A37: Proceeds from issuance of senior notes | B37: — | C37: — | D37: 2,000,000
A38: Payments of debt issuance costs from issuance of senior notes | B38: — | C38: — | D38: (26,619)
A39: Repayments of Paycheck Protection Program Liquidity Facility advances | B39: (480,694) | C39: (16,840) | D39: —
A40: Payments to redeem convertible notes | B40: (1,071,788) | C40: (461,761) | D40: —
A41: Proceeds from warehouse facilities borrowings | B41: 1,620,805 | C41: 1,387,662 | D41: 1,255,745
A42: Repayments of warehouse facilities borrowings | B42: (391,463) | C42: (1,118,083) | D42: (1,329,729)
...
